# Exception is an error
try:
    x = 6
    print(x)
except:
    print("an error occured")
finally:
    print("success")


